<?xml version="1.0"?>
<robot xmlns:xacro="http://www.ros.org/wiki/xacro">
    <xacro:macro name="sub_arm" params="identifier parent xPos yPos zPos roll pitch yaw">
        <link name="${identifier}_arm_base">
            <visual>
                <geometry>
                    <box size="0.0381 0.0509 0.05"/>
                </geometry>
                <origin rpy="0 0 0" xyz="-0.01905 -0.0254 -0.03"/>
            </visual>
        </link>
        <link name="${identifier}_arm_main">
            <visual>
                <geometry>
                    <box size="0.2667 0.0253 0.0262"/>
                </geometry>
                <origin rpy="0 0 0" xyz="0.13335 0 0"/>
            </visual>
        </link>
        <joint name="${identifier}_arm_base_joint" type="fixed">
			<parent link="${parent}"/>
			<child link="${identifier}_arm_base"/>
			<origin xyz="${xPos} ${yPos} ${zPos}" rpy="${roll} ${pitch} ${yaw}"/>
		</joint>
		<joint name="${identifier}_arm_pivot_joint" type="revolute">
		    <parent link="${identifier}_arm_base"/>
		    <child link="${identifier}_arm_main"/>
		    <origin xyz="-0.0191 -0.0254 -0.076" rpy="0 0 0"/>
		    <axis xyz="0 1 0"/>
		    <limit effort="2.8" lower="-1.57" upper="0.2" velocity="20"/>
		</joint>
    </xacro:macro>
</robot>
